Workbook

Sheet Summary
A1: Multiship - QA bug list and coverage
A2: Prepared by Claude (Cowork) for Manoj on 2026-10-16. Counts on this sheet are formulas over the Bugs, Coverage and Screens sheets.
A4: Test details
A5: Application | B5: Multiship
A6: URL | B6: http://localhost:5173
A7: Environment | B7: Local dev (React/Vite UI, /api/v1 proxied to the Java backend); every carrier account in SANDBOX mode
A8: Build(s) tested | B8: local dev, 2026-10-13, local dev, 2026-10-13 (rebuilt after R4; frontend modules dated 13:12 IST), local dev, 2026-10-14 (order-form modules reloaded 13:17 IST), local dev, 2026-10-16
A9: Tested as (role) | B9: admin (ADMIN)
A10: Tested on | B10: 2026-10-11 to 2026-10-16
A11: Reference documents | B11: No SRS/FRD supplied. Expected behaviour taken from carrier API responses, the app's own messages and labels, and consistency between lanes and carriers
A12: Run R1 | B12: 2026-10-11 - Orders > New order: international shipments for client MKL246 to Canada, United Kingdom and Mexico, every carrier x service x packaging (FedEx, UPS, USPS); labels and Order API checked afterwards. Order references QA-1011-R13-*
A13: Run R2 | B13: 2026-10-12 - Settings > Organization (Clients, Warehouses, Address book, Users, Roles): every element of each list, add/edit form and detail view; rest of Settings mapped at menu level
A14: Run R3 | B14: 2026-10-12 - Retest of all 52 findings from R1 and R2 after the backend restart of 2026-10-12: each bug re-walked through its own steps in the interface
A15: Run R4 | B15: 2026-10-13 - Full re-walk of all 53 findings through their own steps, plus a first security and data-sanitation pass: input sanitation and output encoding, access control and tenant isolation, data integrity and storage hygiene, and session, transport and error handling
A16: Run R5 | B16: 2026-10-13 - Full regression of all 67 findings (BUG-001 to BUG-067), each re-walked through its own steps on the rebuilt build, plus an element-by-element pass of every Settings submodule (Organization, Carriers & Services, International, Labels & Documents, Email & Alerts, Integrations, System, Activity & Logs) with security, data-validation and data-sanitation checks on each screen
... A18: Run R7 | B18: 2026-10-16 - R7 retest: the 69 findings marked Fixed by the developers (Fixed in build 2026-10-15, HEAD 5f1d0e52) and the 7 Deferred (BUG-007, 017, 070, 088, 097, 123, 131), each re-walked through its own steps, with a check of neighbouring elements around each fix
A20: Coverage
A21: Screens mapped | B21: =COUNTA(Screens!$A:$A)-1 -> 41
A22: Screens: done | B22: =COUNTIF(Screens!$F:$F,"Done") -> 38
A23: Screens: partial | B23: =COUNTIF(Screens!$F:$F,"Partial") -> 3
A24: Screens: in progress | B24: =COUNTIF(Screens!$F:$F,"In progress") -> 0
A25: Screens: blocked | B25: =COUNTIF(Screens!$F:$F,"Blocked") -> 0
A26: Screens: not started | B26: =COUNTIF(Screens!$F:$F,"Not started") -> 0
A27: Elements listed | B27: =COUNTA(Coverage!$E:$E)-1 -> 438
A28: Elements: pass | B28: =COUNTIF(Coverage!$J:$J,"Pass") -> 344
A29: Elements: fail | B29: =COUNTIF(Coverage!$J:$J,"Fail") -> 67
A30: Elements: blocked | B30: =COUNTIF(Coverage!$J:$J,"Blocked") -> 18
A31: Elements: n/a | B31: =COUNTIF(Coverage!$J:$J,"N/A") -> 0
A32: Elements: not tested | B32: =COUNTIF(Coverage!$J:$J,"Not tested") -> 9
A33: Exercised (of testable elements) | B33: =IF(($B$27-$B$31)=0,0,($B$28+$B$29)/($B$27-$B$31)) -> 0.93835616
A35: Bugs found
A36: Critical | B36: =COUNTIFS(Bugs!$B:$B,"Critical",Bugs!$C:$C,"<>Query",Bugs!$C:$C,"<>Suggestion") -> 0
A37: High | B37: =COUNTIFS(Bugs!$B:$B,"High",Bugs!$C:$C,"<>Query",Bugs!$C:$C,"<>Suggestion") -> 9
A38: Medium | B38: =COUNTIFS(Bugs!$B:$B,"Medium",Bugs!$C:$C,"<>Query",Bugs!$C:$C,"<>Suggestion") -> 44
A39: Low | B39: =COUNTIFS(Bugs!$B:$B,"Low",Bugs!$C:$C,"<>Query",Bugs!$C:$C,"<>Suggestion") -> 94
A40: Total defects | B40: =SUM($B$36:$B$39) -> 147
A41: Queries (need a decision) | B41: =COUNTIF(Bugs!$C:$C,"Query") -> 11
A42: Suggestions | B42: =COUNTIF(Bugs!$C:$C,"Suggestion") -> 4
A44: Fix progress (changes as the Dev status and Tester status columns are updated)
A45: Dev status: New | B45: =COUNTIF(Bugs!$Z:$Z,"New") -> 65
...

Sheet Bugs
A1: Bug ID | B1: Severity | C1: Type | D1: Module | E1: Submodule | F1: Screen | G1: Element | H1: Title | I1: Steps to reproduce | J1: Test data | K1: Expected result | L1: Actual result | M1: Technical evidence | N1: URL | O1: Reproducibility | P1: Screenshots | Q1: Requirement ref | R1: Role | S1: Build | T1: Found on | U1: Run | V1: Screen ID | W1: Also affects | X1: Tester status | Y1: Retest notes | Z1: Dev status | AA1: Assigned to | AB1: Developer comments | AC1: Fixed in build
A2: BUG-001 | B2: High | C2: Validation | D2: Orders | E2: New order | F2: New order form (international) | G2: Ship-from Full name | H2: New shipment (USPS international): label fails for MKL246's default sender name 'MKL'; the shipment check passes it | I2: 1. Open Orders and click + New shipment (/orders/new) 2. Client: MKL246 (ship from 3PL-EAST, the client default); leave Ship from Full name as the profile default 'MKL' 3. Carrier: USPS 4. Ship to: Full name QA Test Recipient, Company QA Test Co, Address line 1 Av Paseo de la Reforma 222, Country Mexico (MX), Phone 5552081234, State / region CMX, City Ciudad de Mexico, Postal code 06600 5. Service level: USPS Priority Mail Intl 6. Packaging THB-PACKAGE, Weight 5; click Add another box, then Apply box 1 to all 7. Customs: Reason of export Sale, FTR exemption NOEEI 30.37(a), Label type PDF, Incoterms DAP 8. Importer of record & customs broker > Add: Type Receiver, Name and Contact QA Test Recipient, same address, city, post code and phone as Ship to > Use for this shipment 9. Items: Description Cotton T-shirt, HS code 61091000, Origin US, Qty 2, Unit value 20.00, Wt 0.5 10. Click Validate shipment 11. Click Generate label | J2: Ship-from Full name 'MKL' (MKL246 profile default). Orders #934105 (Canada, PMI), #934109 (Canada, PMEI), #934147 (UK, PMI), #934186 (Mexico, PMI) | K2: Either the label is created, or the shipment check flags before Generate that USPS international needs a sender full name of first and last name (two words of 2+ letters). | L2: Check said 'Ready to ship — 1 thing to review: USPS normalised the address; review before shipping.' (Canada: 'All checks passed'). Generate label then shows 'The carrier rejected this shipment If provided, fullname must contain at least 2 alphabetic characters, followed by a space, followed by at least another 2 alphabetic characters. (saved as order 934186)' and the order is saved as ERROR. Same result 4 of 4 times (Canada, UK, Mexico; Priority Mail Intl and Priority Mail Express Intl). With Full name changed to 'MKL Shipping' the same shipments generate (#934107, #934108, #934110-#934112, #934148-#934151, #934187-#934190). | M2: GET /api/v1/orders/934186 -> errorDetails.errorMessage 'STAMPS createShipmentSera[pkg 1/2] HTTP 400 ... fullname must contain at least 2 alphabetic characters ...' (Canada #934105: Stamps code 6619409). Orders list shows ERR with tooltip 'CARRIER If provided, fullname must contain ...'. | N2: /orders/new | O2: Always (4 of 4) | P2: BUG-001.jpg, BUG-001-2.jpg, BUG-001-3.jpg | R2: admin (ADMIN) | T2: 2026-10-11 | U2: R1 | V2: S001 | X2: Closed | Y2: 2026-10-12 R3: still-failing - Confirmed with one SANDBOX label, with Manoj's permission. USPS Priority Mail Intl, MKL246 to 1 Canada Square, London E14 5AB, GB, Ship from Full name left at the client default 'MKL'. The check reported 'Ready to ship - 1 thing to review' with Addresses, Package & weight, Account/service/price and Customs all Passed, and Generate label was enabled. Generate then produced the red toast 'The carrier rejected this shipment - If provided, fullname must contain at least 2 alphabetic characters, followed by a space, followed by at least another 2 alphabetic characters. (saved as order 934191)'. GET /api/v1/orders/934191 shows status ERROR with 'STAMPS createShipmentSera[pkg 1/2] HTTP 400 ... error_code 6619409'. The only change is that the toast now names the order it saved. 2026-10-13 R4 (build local dev, 2026-10-13): still-failing - The pre-flight guard is still absent. USPS Priority Mail Intl, MKL246 to 1 Canada Square, London E14 5AB GB, with Ship from Full name left at the client default 'MKL': the check returns 'Ready to ship - 1 thing to review' with Addresses, Package & weight, Account/service/price and Customs all Passed, and Generate label is enabled. No check mentions the sender name. The carrier rejection itself was not re-provoked today - it was confirmed on 2026-10-12 with order #934191 (STAMPS HTTP 400, error_code 6619409) and nothing in the form has changed, so a second order was not spent on it. 2026-10-13 R5 (build local dev, 2026-10-13 (rebuilt after R4; frontend modules dated 13:12 IST)): fixed - Fixed by outcome. USPS Priority Mail Intl, MKL246 to 1 Canada Square, London E14 5AB GB, 2 x THB-PACKAGE 5 lb, Ship from Full name left at the client default 'MKL' (the validate request carries shipFrom.name 'MKL'). The check still does not mention the sender name - it returns 'Ready to ship - 1 thing to review' with Addresses Passed and localErrors [] - but Generate label now succeeds: order #934192 (reference QA-1013-R5-GB-US-PMI-MKL) was created as GENERATED with tracking CJ000000005US and no errorDetails, where #934191 was refused by Stamps with error 6619409 on the same lane. The bug allowed either outcome ('the label is created, or the check flags it'), and the label is now created. Note for the developers: the 'USPS international needs a sender full name' message described in the fix was not seen anywhere in the interface on this lane. | Z2: Fixed | AB2: Fixed on dev (70ae2636): SERA fullname guard shipped 2026-10-12; verified via curl: validate returns "USPS international needs a sender full name" as sender.name error. QA R4 ran against stale FE bundle. Rebuild + retest. | AC2: 2026-10-13
A3: BUG-002 | B3: High | C3: Functional | D3: Orders | E3: New order | F3: New order form (international) | G3: Item Pkg# | H3: New shipment (USPS international, 2 boxes): with all item lines in box 1, box 2 fails 'Missing customs lines' after box 1 already went to the carrier | I3: 1. Open Orders and click + New shipment (/orders/new) 2. Client: MKL246 (ship from 3PL-EAST, the client default); set Ship from Full name to 'MKL Shipping' 3. Carrier: USPS 4. Ship to: QA Test Recipient, QA Test Co, Toronto ON M5V 3L9, Canada (as for the other Canada orders of the run) 5. Service level: USPS Priority Mail Intl 6. Packaging THB-PACKAGE, Weight 5; Add another box; Apply box 1 to all 7. Customs: Reason of export Sale, Label type PDF, Incoterms DAP 8. Importer of record & customs broker > Add: Type Receiver, Name and Contact QA Test Recipient, same address, city, post code and phone as Ship to > Use for this shipment 9. Items: one line Cotton T-shirt, HS 61091000, Origin US, Qty 2, Unit value 20.00, Wt 0.5; leave Boxes on 'All in box 1' (Pkg # 1) 10. Click Validate shipment, then Generate label | J3: Order #934106 (QA-1011-R13-CA-US-PMI-THB-NM) | K3: The check warns that USPS needs customs lines on every box (or the lines are split across the boxes automatically) before the label is bought; nothing is booked for part of the shipment. | L3: Check: 'All checks passed'. Generate label: 'Missing customs lines.'; order #934106 saved as ERROR. The error names package 2 of 2, so package 1 had already passed its carrier call; the app shows nothing about whether package 1 was booked or voided at USPS (not verified). With two lines of Qty 1 spread across the boxes (Spread across 2 boxes) the same shipment generates (#934108, #934110-#934112, #934148-#934151, #934187-#934190). | M3: GET /api/v1/orders/934106 -> errorDetails.errorMessage 'STAMPS createShipmentSera[pkg 2/2] HTTP 400 ... Missing customs lines.' | N3: /orders/new | O3: 1 of 1 (not repeated, to avoid further carrier bookings) | P3: BUG-002.jpg, BUG-002-2.jpg, BUG-002-3.png | R3: admin (ADMIN) | T3: 2026-10-11 | U3: R1 | V3: S001 | X3: Closed | Y3: 2026-10-12 R3: fixed - The pre-flight now catches it. With two boxes and every item line in box 1, the check reports '1 issue to fix before the label can be bought' and under Package & weight: 'Box 2 has no customs lines. Every box in a multi-box international shipment needs at least one item - redistribute items or remove the box.' Generate label stays disabled and Carrier check reads 'Not checked', so nothing is sent to the carrier. After spreading the lines across the boxes the check passes. Nothing is now booked for part of a shipment. 2026-10-13 R4 (build local dev, 2026-10-13): fixed - Re-walked. With two boxes and every item line put in box 1, the check returns '1 issue to fix before the label can be bought' and under Package & weight: 'Box 2 has no customs lines. Every box in a multi-box international shipment needs at least one item - redistribute items or remove the box.' Generate label stays disabled and Carrier check reads 'Not checked', so the carrier is never called for a part-filled shipment. 2026-10-13 R5 (build local dev, 2026-10-13 (rebuilt after R4; frontend modules dated 13:12 IST)): fixed - Regression check passed. Same USPS shipment to London with two boxes and the only item line in box 1: the check returns '1 issue to fix before the label can be bought' with Package & weight 'Box 2 has no customs lines. Every box in a multi-box international shipment needs at least one item - redistribute items or remove the box.', Carrier check 'Not checked' and Generate label disabled. | Z3: New
A4: BUG-003 | B4: Medium | C4: Validation | D4: Orders | E4: New order | F4: New order form (international) | G4: Add another box | H4: New shipment: single-piece carrier packagings (FedEx Envelope, 10kg, 25kg box; UPS 10KG, 25KG box) accept a second box, then the carrier rejects the label | I4: 1. Open Orders and click + New shipment (/orders/new) 2. Client: MKL246 (ship from 3PL-EAST, the client default) 3. Carrier: FedEx 4. Ship to: QA Test Recipient, Toronto ON M5V 3L9, Canada 5. Service level: FedEx International Priority 6. Packaging FedEx 10kg Box, Weight 10 7. Click Add another box, then Apply box 1 to all (2 boxes) 8. Customs: Reason of export Sale, Export declaration ref 'NO EEI 30.36', Label type PDF, Label size Paper 4x6, Incoterms DAP 9. Importer of record & customs broker > Add: Type Receiver, Name and Contact QA Test Recipient, same address, city, post code and phone as Ship to > Use for this shipment 10. Items: Description Cotton T-shirt, HS code 61091000, Origin US, Qty 2, Unit value 20.00, Wt 0.5 11. Click Validate shipment, then Generate label 12. Repeat with FedEx Envelope (International Economy and Priority), FedEx 25kg Box, and with carrier UPS, Worldwide Saver and Worldwide Express, UPS 10KG Box (10 lb) and UPS 25KG Box (20 lb) | J4: FedEx: #934063 (IE Envelope), #934068 (IP 10kg), #934069 (IP 25kg), #934070 (IP Envelope). UPS: #934079, #934080 (Saver 10KG/25KG), #934091, #934092 (Express 10KG/25KG) | K4: The form allows only one box for these single-piece packagings, or the check blocks Generate with a message about the box count. | L4: FedEx check: ready to ship with one item to review, the note 'Multi-package validate: FedEx only supports single-piece pre-flight; box 1 validated, boxes 2–2 verified at label create'. Label: 'The package count for this shipment exceeds limit.' UPS check: ready to ship with one item to review (the UPS rate call returned HTTP 400 with the same message as below), Carrier check passed and Generate enabled; label: 'The requested service is not valid for shipments with the requested packaging.', which is misleading because the same service and packaging generate as one box (#934075-#934078, #934093, #934094, #934103, #934104 and every UK/Mexico 1-box order). 8 of 8 two-box attempts failed. | M4: API errorDetails: 'FEDEX createShipment HTTP 400 ... The package count for this shipment exceeds limit.' (#934063, #934068-#934070); 'UPS createShipment HTTP 400 ... The requested service is not valid for shipments with the requested packaging.' (#934079, #934080, #934091, #934092) | N4: /orders/new | O4: Always (8 of 8 two-box attempts; 0 failures as one box) | P4: BUG-003.jpg, BUG-003-2.jpg, BUG-003-3.jpg, BUG-003-4.jpg, BUG-003-5.png, BUG-003-6.png | R4: admin (ADMIN) | T4: 2026-10-11 | U4: R1 | V4: S001 | X4: Closed | Y4: 2026-10-12 R3: fixed - Single-piece packagings now refuse extra boxes. With FedEx Envelope, both 'Add another box' and 'Add N boxes like the last' are disabled=true with the tooltip 'FedEx Envelope ships at most 1 box per label. If you need to ship more than one box, create each one as a separate shipment.'; UPS 10KG Box gives the same guard. With an extra box already on the form, switching to UPS 10KG Box raises an inline warning naming the consequence: 'UPS 10KG Box ships at most 1 box per label - the carrier will reject this 2-box shipment. Remove the extra boxes or pick a larger packaging.' The label is no longer bought and then rejected. Note the new BUG-053: in exactly that state the Validate button goes silent. 2026-10-13 R4 (build local dev, 2026-10-13): fixed - Re-walked on UPS. With UPS 10KG Box selected, 'Add another box' and 'Add N boxes like the last' are both disabled=true with the tooltip 'UPS 10KG Box ships at most 1 box per label. To ship multiple boxes, create each one as a separate shipment.', and an existing extra box raises the inline warning 'UPS 10KG Box ships at most 1 box per label - the carrier will reject this 2-box shipment. Remove the extra boxes or pick a larger packaging.' 2026-10-13 R5 (build local dev, 2026-10-13 (rebuilt after R4; frontend modules dated 13:12 IST)): fixed - Regression check passed on FedEx: with FedEx International Priority and Packaging 'FedEx 10kg Box', both 'Add another box' and 'Add N boxes like the last' are disabled with the tooltip 'FedEx 10kg Box ships at most 1 box per label. If you need to ship more than one box, create each one as a separate shipment.' (UPS checked separately under BUG-053). UPS checked too: with UPS 10KG Box selected and two boxes already on the form, 'Add another box' and 'Add N boxes like the last' are disabled with 'UPS 10KG Box ships at most 1 box per label. To ship multiple boxes, create each one as a separate shipment.', and the inline warning names the 2-box conflict. | Z4: New
A5: BUG-004 | B5: Medium | C5: Functional | D5: Orders | E5: New order | F5: New order form (international) | G5: Shipment check panel | H5: Shipment check (FedEx International Priority): '1 issue to fix: FEDEX did not quote FedEx International Priority' although IP is in the quoted list; Generate stays enabled | I5: 1. Open Orders and click + New shipment (/orders/new) 2. Client: MKL246 (ship from 3PL-EAST, the client default) 3. Carrier: FedEx 4. Ship to: Full name QA Test Recipient, Company QA Test Co, Address line 1 Av Paseo de la Reforma 222, Country Mexico (MX), Phone 5552081234, State / region CMX, City Ciudad de Mexico, Postal code 06600 5. Service level: FedEx International Priority 6. Packaging THB-PACKAGE, Weight 5 (one box) 7. Customs: Reason of export Sale, Label type PDF, Incoterms DAP 8. Importer of record & customs broker > Add: Type Receiver, Name and Contact QA Test Recipient, same address, city, post code and phone as Ship to > Use for this shipment 9. Items: Description Cotton T-shirt, HS code 61091000, Origin US, Qty 2, Unit value 20.00, Wt 0.5 10. Click Validate shipment | J5: Retest 2026-10-12, reference QA-1012-EVID-MX-FX-IP (validated only, not saved), and the same on a UK tube shipment. During the run: every International Priority shipment whose FedEx rate call succeeded, e.g. #934072, #934074, #934118, #934122, #934157, #934161-#934163 | K5: No issue when the selected service is in the quoted list. A check that says an issue must be fixed before the label can be bought should also keep Generate disabled. | L5: Check header '1 issue to fix before the label can be bought · 1 to review'; Account, service & price '1 to fix': 'FEDEX did not quote FedEx International Priority for this lane — the label may be refused. Quoted instead: FedEx International Connect Plus — USD 159.18; FedEx International Economy® — USD 174.95; FedEx International Priority® — USD 218.58; FedEx International Priority® Express — USD 229.64; FedEx International First® — USD 271.64.' The same sentence is listed twice (as to fix and to review) and again in the price box. Generate label stays enabled and the labels generate. Seen for Canada, UK and Mexico; retested 2026-10-12 for Mexico and UK. | M5: The quoted list contains 'FedEx International Priority®' (with the registered mark), which may be why the match on the service name fails. No console capture. | N5: /orders/new | O5: Always when the FedEx rate call succeeds | P5: BUG-004.jpg, BUG-004-2.jpg, BUG-004-3.jpg, BUG-004-4.jpg, BUG-004-5.png, BUG-004-6.jpg, BUG-004-7.jpg, BUG-004-8.jpg, BUG-004-9.jpg, BUG-004-10.png, BUG-004-11.png | R5: admin (ADMIN) | T5: 2026-10-11 | U5: R1 | V5: S001 | X5: Closed | Y5: 2026-10-12 R3: fixed - FedEx International Priority to Mexico (MKL246, THB-PACKAGE 5 lb, importer Receiver) now returns 'All checks passed - ready to generate the label' with Account, service & price Passed and the detail 'PRICE & DELIVERY - FEDEX INTERNATIONAL PRIORITY(R) Price USD 218.58 Billed weight 5 lb > Other FEDEX services on this lane (4)'. The contradictory 'FEDEX did not quote FedEx International Priority' issue is gone and the selected service is matched to the quote. 2026-10-13 R4 (build local dev, 2026-10-13): fixed - FedEx International Priority to Ciudad de Mexico now matches the selected service to the quote: Account, service & price shows 'PRICE & DELIVERY - FEDEX INTERNATIONAL PRIORITY / Billed weight 4 lb' and the contradictory 'FEDEX did not quote FedEx International Priority' issue is gone. The only note on this run was a genuine sandbox outage - 'No price: FEDEX rate call failed - HTTP 503 The service is currently unavailable' - which is the carrier being down, not the bug. 2026-10-13 R5 (build local dev, 2026-10-13 (rebuilt after R4; frontend modules dated 13:12 IST)): fixed - Regression check passed once the FedEx sandbox answered (the first two validations got 'HTTP 503'). FedEx International Priority, MKL246 to Av Paseo de la Reforma 222, Ciudad de Mexico CMX 06600, THB-PACKAGE 5 lb: the check reads 'All checks passed - ready to generate the label' with Account, service & price Passed; the quote is QUOTED 'FedEx International Priority(R)' USD 218.58, with Connect Plus 159.18, Economy 174.95, Priority Express 229.64 and First 271.64 listed as alternatives. The contradictory 'FEDEX did not quote FedEx International Priority' issue does not appear. | Z5: New
A6: BUG-005 | B6: Medium | C6: Usability | D6: Orders | E6: New order | F6: New order form (international) | G6: FTR exemption (UK, Mexico) | H6: New shipment (FedEx to Canada): no FTR exemption field; with Export declaration ref empty FedEx rejects 'FTR Exemption or AES Citation ... not valid for EEI' | I6: 1. Open Orders and click + New shipment (/orders/new) 2. Client: MKL246 (ship from 3PL-EAST, the client default) 3. Carrier: FedEx 4. Ship to: Full name QA Test Recipient, Company QA Test Co, Address line 1 290 Bremner Blvd, Country Canada (CA), Phone 4165550100, State / region ON, City Toronto, Postal code M5V 3L9 5. Service level: FedEx International Economy 6. Packaging FedEx Pak, Weight 2 (one box) 7. Customs: Reason of export Sale; note there is no FTR exemption or AES ITN field for Canada; leave Export declaration ref empty; Label type PDF; Label size Paper 4x6; Incoterms DAP 8. Importer of record & customs broker > Add: Type Receiver, Name and Contact QA Test Recipient, same address, city, post code and phone as Ship to > Use for this shipment 9. Items: Description Cotton T-shirt, HS code 61091000, Origin US, Qty 2, Unit value 20.00, Wt 0.5 10. Click Validate shipment | J6: Retest 2026-10-12, reference QA-1012-EVID-CA-FX-IE (validated only, not saved). During the run all Canada FedEx orders (#934063-#934078) needed the workaround | K6: Canada gets the same FTR exemption dropdown as the UK and Mexico forms (which already list 'NOEEI §30.36 — export to Canada'), or a valid default, so a low-value shipment passes without typing a citation. | L6: Carrier check '1 to fix': 'FedEx rejected the shipment: The FTR Exemption or AES Citation you provided is not valid for EEI.' Generate label stays disabled, while 'Customs & dangerous goods' shows Passed. Typing 'NO EEI 30.36' into Export declaration ref makes the check pass. | M6: Canada form selects: Reason of export, Currency, Label type, Label size, Pickup type, Incoterms, Duties paid by - no FTR exemption (UK and Mexico forms have it). | N6: /orders/new | O6: Always | P6: BUG-005.jpg, BUG-005-2.jpg, BUG-005-3.png, BUG-005-4.png | R6: admin (ADMIN) | T6: 2026-10-11 | U6: R1 | V6: S001 | X6: Closed | Y6: 2026-10-12 R3: fixed - The Canada form now carries an FTR EXEMPTION dropdown and an AES ITN (CENSUS) field next to Reason of export. The dropdown offers '-- None (using AES) --', 'NOEEI 30.37(a) - value under $2,500 USD', 'NOEEI 30.37(h) - tools of trade / temporary export' and 'NOEEI 30.36 - export to Canada'. With Export declaration ref left empty and the exemption left at None, Validate shipment returned all five checks Passed, Carrier check included - the 'FTR Exemption or AES Citation you provided is not valid for EEI' refusal is gone. 2026-10-13 R4 (build local dev, 2026-10-13): fixed - The FTR EXEMPTION dropdown and AES ITN (CENSUS) field are present on the Canada form. A Canada shipment validated with the exemption left at '-- None (using AES) --' and Export declaration ref empty returned all five checks Passed, Carrier check included. 2026-10-13 R5 (build local dev, 2026-10-13 (rebuilt after R4; frontend modules dated 13:12 IST)): fixed - Fixed as the bug asked: the Canada form now has the FTR EXEMPTION dropdown (None (using AES), NOEEI 30.37(a), NOEEI 30.37(h), NOEEI 30.36 - export to Canada) and an AES ITN (CENSUS) field. With the original steps (FedEx International Economy, FedEx Pak 2 lb, Toronto ON M5V 3L9, Export declaration ref empty) and 'NOEEI 30.36 - export to Canada' picked, the check returns 'Local + FEDEX checks passed. Ready to generate the label.' with no citation typed. Unlike R4, though, leaving the exemption at its default '-- None (using AES) --' now gets 'FedEx rejected the shipment: The FTR Exemption or AES Citation you provided is not valid for EEI.' again (2 of 2 validations, IE/Pak and IP/10kg Box), while Customs & dangerous goods says Passed - logged separately as a new validation finding. | Z6: New
A7: BUG-006 | B7: Medium | C7: Functional | D7: Orders | E7: New order | F7: New order form (international) | G7: Add N boxes like the last | H7: New shipment: 'Add N boxes like the last' copies the weight but leaves Length / Width / Height empty for a carrier box | I7: 1. Open Orders and click + New shipment (/orders/new) 2. Client: MKL246 (ship from 3PL-EAST, the client default) 3. Carrier: UPS 4. Ship to country Mexico 5. Service level: UPS Worldwide Saver 6. Packaging UPS Large Express Box, Weight 4 7. Set the box count next to 'boxes like the last' to 1 8. Click 'boxes like the last' (tooltip: 'Adds boxes copying the last box's weight and dimensions (box 1's when there is no extra box yet)') | J7: Seen on MX-UP-WWS-LBOX (#934168) during the run; retested 2026-10-12 (form not saved) | K7: Box 2 gets weight 4 lb and the box's dimensions 18 x 13 x 3 in, as the tooltip says. | L7: Box 2 shows Weight 4 and empty L, W and H fields. Apply box 1 to all fills them (18 x 13 x 3). | M7: Box card after the click: 'BOX 2 ... Weight (lb) 4, L (in) [empty], W (in) [empty], H (in) [empty]' | N7: /orders/new | O7: Always (2 of 2) | P7: BUG-006.jpg, BUG-006-2.jpg, BUG-006-3.jpg | R7: admin (ADMIN) | T7: 2026-10-11 | U7: R1 | V7: S001 | X7: Closed | Y7: 2026-10-12 R3: fixed - Retested on the exact original repro: UPS Large Express Box, weight 4, 'Add 1 boxes like the last'. Box 2 now reads 'BOX 2 4 lb - 18x13x3 in' - the dimensions are copied as well as the weight, and the extra box is shown as a compact summary with Duplicate / Edit / delete. Same result with a Custom package carrying 18x13x3. One gap remains: for THB-PACKAGE, which has no dimension fields of its own, box 2 still opens with empty L, W and H. 2026-10-13 R4 (build local dev, 2026-10-13): fixed - Re-walked on the original repro: UPS Large Express Box, weight 4, 'Add 1 boxes like the last' gives 'BOX 2 4 lb - 18x13x3 in'. Weight and dimensions are both copied. 2026-10-13 R5 (build local dev, 2026-10-13 (rebuilt after R4; frontend modules dated 13:12 IST)): fixed - Regression check passed: UPS Large Express Box, weight 4, 'Add 1 boxes like the last' gives 'BOX 2 4 lb - 18x13x3 in' - weight and dimensions both copied (checked on the Canada lane). | Z7: New
A8: BUG-007 | B8: Medium | C8: Functional | D8: Orders | E8: Label | F8: Label documents | G8: Label preview | H8: Label documents #934118: label stored as a FedEx document link instead of the PDF; each label request takes 3-4 s and the page shows 'Loading label document...' for about 8 s | I8: 1. Open /label/934118 (Orders > order #934118 > View label) 2. Watch the label area and the Download / Print buttons 3. Compare with /label/934119 (same carrier, service and lane) | J8: Order #934118 (QA-1011-R13-GB-FX-IP-10KG-1B), FedEx International Priority to the UK | K8: The label is stored like the other 114 labels and the page shows it within a second. | L8: 'Loading label document...' with Download PDF, Download .zpl, Copy ZPL and Print Label disabled until about 12 s after opening the page (about 3 s for #934119), then the label renders. The order's labelDetails.labelFilePath holds 'https://wwwtest.fedex.com/document/v1/cache/retrieve/SH...' (124 characters) while the other 114 generated orders hold the base64 PDF. Whether that FedEx link expires was not verified. | M8: GET /api/v1/orders/934118/label 3.6-4.3 s, GET /api/v1/orders/934118/label/pdf 3.4 s; for #934119: 55-109 ms and 21 ms (browser resource timing, 2026-10-12). | N8: /label/934118 | O8: Always for #934118 (1 of 115 labels) | P8: BUG-007.jpg, BUG-007-R7.jpg | R8: admin (ADMIN) | T8: 2026-10-11 | U8: R1 | V8: S003 | W8: API > Orders > Order detail (GET /api/v1/orders/{id}) | X8: Reopened | Y8: 2026-10-12 R3: still-failing - Unchanged. /label/934118 shows 'Loading label document...' with Download PDF, Download .zpl, Copy ZPL and Print Label disabled for about 10-12 seconds (about 3 seconds for /label/934119 on the same carrier and lane). GET /api/v1/orders/934118 still returns labelDetails.labelFilePath as a 124-character 'https://wwwtest.fedex.com/document/v1/cache/retrieve/SH...' link while the other generated orders hold the base64 PDF (934119: 18,376 characters; 934190: 133,684). The rendered document is also still the one-page FedEx text placeholder rather than the 4-page SANDBOX label the other orders show. 2026-10-13 R4 (build local dev, 2026-10-13): still-failing - Unchanged on the 2026-10-13 build. GET /api/v1/orders/934118 still returns labelDetails.labelFilePath as a 124-character https://wwwtest.fedex.com/document/v1/cache/retrieve/... link, while every other generated order holds the base64 PDF (934119: 18,376 characters; 934172: 59,768; 934190: 133,684). The label page for 934118 still sits on 'Loading label document...' with the download and print buttons disabled for roughly ten seconds against about three for the others. 2026-10-13 R5 (build local dev, 2026-10-13 (rebuilt after R4; frontend modules dated 13:12 IST)): still-failing - New labels are fine; the order in the bug is not, and the guard itself could not be exercised. A new FedEx International Priority label to the UK (order #934193, 2 x FedEx Tube, reference QA-1013-R5-GB-FX-IP-TUBE-2B, generated with Manoj's permission) is stored as a PDF - labelDetails.labelFilePath is an 18,308-character base64 string starting %PDF - and /label/934193 renders at once (GET /label 184-248 ms, /label/pdf 36 ms). But the original fault hit 1 label in 115, so one clean label does not show that the new URL-only guard works, and FedEx cannot be made to return a link-only label on demand. Order #934118 itself is unchanged: GET /api/v1/orders/934118 still returns a 124-character https://wwwtest.fedex.com/document/... link and GET /label takes 2.3 s against 63 ms for #934119. The developers say an admin label-backfill endpoint can repair it; that endpoint is not in the interface, so it was not run. Please run it for #934118 and the order can be re-checked. 2026-10-14 R6 (build local dev, 2026-10-14 (order-form modules reloaded 13:17 IST)): still-failing - R6: unchanged - the backfill has not been run. /label/934118 still opens on 'Loading label document...' with Download PDF, Download .zpl, Copy ZPL and Print Label disabled; GET /api/v1/orders/934118 takes about 4.0 s and its labelDetails.labelFilePath is still the 124-character https://wwwtest.fedex.com/document/... link; GET /label 3.9 s and the two preview.png requests 4.5 s and 6.0 s. 2026-10-16 R7 (build local dev, 2026-10-16): still-failing - unchanged - the backfill the developers describe has not been run. /label/934118 opens on 'Loading label document...' with Download PDF, Download .zpl, Copy ZPL and Print Label disabled, the header enables at about 6 s and the label renders at about 12 s (screenshots at 1, 6 and 12 s); /label/934119 renders within 2 s. GET /api/v1/orders/934118 still returns labelDetails.labelFilePath as the 124-character https://wwwtest.fedex.com/document/... link while #934172, #934190 and #934192 hold base64 PDFs (59,768 to 133,684 characters). New labels bought in this run (#934195, #934196) are stored as PDF and open at once. Needs the admin label-backfill run for #934118, then a recheck. | Z8: Deferred | AB8: Deferred to next round: Needs backfill endpoint invocation for #934118; no new code. | AC8: 2026-10-13
A9: BUG-008 | B9: Low | C9: Usability | D9: Orders | E9: New order | F9: New order form (international) | G9: State / region (UK, Mexico) | H9: New shipment (ship to Mexico): State / region is required but has no * marker, a US placeholder 'NY', and accepts only ISO codes as free text | I9: 1. Open Orders and click + New shipment (/orders/new) 2. Client: MKL246 (ship from 3PL-EAST, the client default) 3. Carrier: FedEx 4. Ship to country Mexico; fill name, address, city Ciudad de Mexico, postal code 06600; leave State / region empty 5. Complete the rest of the form and click Validate shipment 6. Enter DF in State / region and click Validate shipment again | J9: Retest 2026-10-12 (QA-1012-EVID-MX-FX-IP, not saved); during the run every Mexico order needed CMX | K9: Required fields carry the * marker used elsewhere on the form, and Mexico offers a state dropdown like Canada's province list, so a valid code is picked rather than guessed. | L9: The label 'STATE / REGION' has no * (City * and Postal code * do), and the placeholder is 'NY'. Empty: toast '1 field needs attention — Ship to state: state / region is required' and the field turns red. 'DF' is accepted by the field and only rejected by the check; 'CMX' works. The run notes recorded Validate doing nothing visible; on retest the toast appeared, so that part is not reported. | N9: /orders/new | O9: Always | P9: BUG-008.jpg, BUG-008-2.jpg, BUG-008-3.png, BUG-008-4.jpg, BUG-008-5.jpg, BUG-008-6.png, BUG-008-7.png | R9: admin (ADMIN) | T9: 2026-10-11 | U9: R1 | V9: S001 | X9: Closed | Y9: 2026-10-12 R3: still-failing - Two of the three parts are fixed. The label now reads 'STATE / REGION *' with the red asterisk the other required fields carry, and the placeholder for Mexico is now 'CMX', a real Mexican state code, not the US 'NY'. What remains: the field is still a free-text input for Mexico, not a dropdown of Mexican states the way Canada gets a province list and the US gets a state list - and it silently accepts a value carried over from another country (switching Canada to Mexico left 'ON' in the box, which only the carrier check later rejects). 2026-10-13 R4 (build local dev, 2026-10-13): fixed - Mexico now gets a proper state list. With the country set to Mexico, State / region becomes a 32-entry dropdown (AGU - Aguascalientes, BCN - Baja California, BCS - Baja California Sur, CAM - Campeche, CHP - Chiapas and the rest) with the required asterisk on the label. The US placeholder 'NY' and the free-typed guessing are both gone, and a value carried over from another country can no longer survive the switch. 2026-10-13 R5 (build local dev, 2026-10-13 (rebuilt after R4; frontend modules dated 13:12 IST)): fixed - Regression check passed: with Ship to country Mexico, State / region is a dropdown of 32 states (AGU - Aguascalientes ... CMX - Ciudad de Mexico ...) labelled 'STATE / REGION *'; the postal code placeholder reads 'e.g. 01000'. Changing the state does not clear City or Postal code. | Z9: New
A10: BUG-009 | B10: Low | C10: Content | D10: Orders | E10: New order | F10: New order form (international) | G10: Shipment check panel | H10: Shipment check (Mexico): state message says 'Use the 2-letter code (e.g. CMX, JAL, NLE)' but every example is three letters | I10: 1. Open Orders and click + New shipment (/orders/new) 2. Client: MKL246 (ship from 3PL-EAST, the client default) 3. Carrier: FedEx 4. Ship to country Mexico with State / region DF 5. Complete the form and click Validate shipment | J10: QA-1012-EVID-MX-FX-IP (validated only) | K10: The message asks for the 3-letter state code (CMX, JAL, NLE). | L10: Addresses '1 to fix': 'State/province "DF" isn't a valid MX code. Use the 2-letter code (e.g. CMX, JAL, NLE), not the full name.' | N10: /orders/new | O10: Always | P10: BUG-009.jpg, BUG-009-2.jpg, BUG-009-3.png | R10: admin (ADMIN) | T10: 2026-10-12 | U10: R1 | V10: S001 | X10: Closed | Y10: 2026-10-12 R3: fixed - The check message now reads: 'State/province "DF" isn't a valid MX code. Use the official code (e.g. CMX, JAL, NLE), not the full name.' The wrong '2-letter code' wording is gone, so the instruction and the examples agree. 2026-10-13 R4 (build local dev, 2026-10-13): fixed - Unreachable by design now. Because Mexico's State / region is a dropdown of official codes, an invalid value such as DF cannot be typed, so the message 'Use the 2-letter code (e.g. CMX, JAL, NLE)' no longer appears. The wording was already corrected to 'Use the official code' on 2026-10-12. 2026-10-13 R5 (build local dev, 2026-10-13 (rebuilt after R4; frontend modules dated 13:12 IST)): fixed - Regression check passed: the message cannot be reached any more because Mexico's State / region only offers official codes from a dropdown, so an invalid value such as DF cannot be entered. | Z10: New
A11: BUG-010 | B11: Low | C11: Content | D11: Orders | E11: New order | F11: New order form (international) | G11: Importer of record & customs broker: Add | H11: New shipment (Mexico): Importer section shows the badge 'RESOLVED FOR MX' next to the warning 'No importer/broker profile covers MX for MKL246' | I11: 1. Open Orders and click + New shipment (/orders/new) 2. Client: MKL246 (ship from 3PL-EAST, the client default) 3. Carrier: USPS (also seen with FedEx) 4. Ship to country Mexico 5. Look at the Importer of record & customs broker section before adding an override | J11: Seen 2026-10-12 (forms not saved) | K11: The badge and the message agree: no profile means no 'resolved' badge (the FedEx ship-to card also shows 'Importer/broker resolved for MX'). | L11: Badge 'RESOLVED FOR MX' and, below it, 'No importer/broker profile covers MX for MKL246. Click Add to enter importer/broker for this shipment only'. | N11: /orders/new | O11: Always | P11: BUG-010.jpg, BUG-010-2.jpg, BUG-010-3.png | R11: admin (ADMIN) | T11: 2026-10-12 | U11: R1 | V11: S001 | X11: Closed | Y11: 2026-10-12 R3: fixed - For a Mexico shipment with no importer profile, the badge now reads 'NOT CONFIGURED' in grey next to the message 'No importer/broker profile covers MX for MKL246. Click Add to enter importer/broker for this shipment only (the client's saved profile is not changed).' The contradictory 'RESOLVED FOR MX' badge is gone. Once an override is entered the badge becomes 'OVERRIDDEN - THIS SHIPMENT' and the Ship to card shows the green 'Importer/broker resolved for CA' chip - both now only when something really is resolved. 2026-10-13 R4 (build local dev, 2026-10-13): fixed - On a Canada shipment with no importer profile the badge reads 'NOT CONFIGURED' beside 'No importer/broker profile covers CA for MKL246...', and on a UK shipment the Ship to card reads the amber 'No importer/broker profile for GB - set one up'. The badge only says resolved once an override is actually applied. 2026-10-13 R5 (build local dev, 2026-10-13 (rebuilt after R4; frontend modules dated 13:12 IST)): fixed - Regression check passed on the Mexico lane: before an override the Importer section reads 'NOT CONFIGURED' beside 'No importer/broker profile covers MX for MKL246. Click Add to enter importer/broker for this shipment only...', and after Receiver - DAP is applied it reads 'OVERRIDDEN - THIS SHIPMENT'. No 'resolved' badge appears without a profile. | Z11: New
A12: BUG-011 | B12: Low | C12: Usability | D12: Orders | E12: New order | F12: New order form (international) | G12: Item HS code and lookup | H12: New shipment (Canada): HS code lookup suggests the 6-digit 610910, which the form then rejects as too short | I12: 1. Open Orders and click + New shipment (/orders/new) 2. Client: MKL246 (ship from 3PL-EAST, the client default) 3. Carrier: FedEx 4. Ship to country Canada 5. Items: Description Cotton T-shirt; take the HS code the lookup suggests | J12: First Canada shipment of the run (2026-10-11) | K12: The lookup offers a code long enough for the destination (8+ digits for Canada). | L12: Lookup gives 610910; inline error 'CA needs at least an 8-digit HS code (you entered 6)'. 61091000 typed by hand is accepted. | N12: /orders/new | O12: Seen once (not retested) | P12: BUG-011.png | R12: admin (ADMIN) | T12: 2026-10-11 | U12: R1 | V12: S001 | X12: Closed | Y12: 2026-10-12 R3: fixed - Typing 't-shirt' into HS code on a Canada shipment still lists 610910 and 610990, but picking 610910 now inserts 61091000 into the field - the lookup pads the code to the destination's required length. No inline error, and the Customs check passed. The hint under the field reads 'HS code should be 6-10 digits (e.g. 6104.62.20). Dots/spaces are OK; letters are not.' 2026-10-13 R4 (build local dev, 2026-10-13): fixed - Typing 't-shirt' into HS code on a Canada shipment lists 610910 and 610990; picking 610910 inserts 61091000 into the field. The code is padded to the destination's required length and the Customs check passes. 2026-10-13 R5 (build local dev, 2026-10-13 (rebuilt after R4; frontend modules dated 13:12 IST)): fixed - Regression check passed: typing t-shirt into HS code on the Canada shipment lists 610910 and 610990, and picking 610910 fills the field with 61091000, the 8 digits Canada needs. The suggestion list itself is too narrow to read - logged separately. | Z12: New
A13: BUG-012 | B13: Low | C13: Content | D13: Orders | E13: New order | F13: New order form (international) | G13: Ship-from address (from client profile) | H13: Client MKL246 ship-from address: Address line 1 '8191 Logistics Dr,' ends with a stray comma | I13: 1. Open Orders and click + New shipment (/orders/new) 2. Client: MKL246 (ship from 3PL-EAST, the client default) 3. Look at Ship from > Address line 1 | J13: MKL246 / 3PL-EAST ship-from profile | K13: Address line 1 without trailing punctuation; it is printed on labels and sent to the carriers. | L13: '8191 Logistics Dr,' | N13: /orders/new | O13: Always | P13: BUG-012.jpg | R13: admin (ADMIN) | T13: 2026-10-11 | U13: R1 | V13: S001 | X13: Closed | Y13: 2026-10-12 R3: still-failing - Client MKL246's ship-from Address line 1 still reads '8191 Logistics Dr,' with the trailing comma, on the New shipment form at /orders/new. 2026-10-13 R4 (build local dev, 2026-10-13): still-failing - Unchanged. Picking client MKL246 on the New shipment form still fills Ship from Address line 1 as '8191 Logistics Dr,' with the trailing comma. 2026-10-13 R5 (build local dev, 2026-10-13 (rebuilt after R4; frontend modules dated 13:12 IST)): fixed - Picking client MKL246 on /orders/new now fills Ship from Address line 1 as '8191 Logistics Dr' with no trailing comma (Ship from 3PL-EAST - Central Warehouse, Zeeland MI 49464). The validate request sends addressLine1 '8191 Logistics Dr' to the server as well. | Z13: Fixed | AB13: Fixed on dev (a0238990): V149 strips trailing comma from warehouse.line1/line2 (3PL-EAST was leaking the string onto labels; V147 only touched clients table). | AC13: 2026-10-13
A14: BUG-013 | B14: Low | C14: Usability | D14: Orders | E14: New order | F14: New order form (international) | G14: Add item | H14: New shipment > Items: 'Add item' inserts the new blank line above the existing one | I14: 1. Open Orders and click + New shipment (/orders/new) 2. Client: MKL246 (ship from 3PL-EAST, the client default) 3. Carrier: USPS; ship to country Mexico 4. Fill item line 1: Cotton T-shirt, 61091000, US, 1, 20.00, 0.5 5. Click + Add item | J14: Seen during the run (USPS split shipments) and on retest 2026-10-12 | K14: The new line is added below the existing line, or focus moves into the new line. | L14: A blank line appears as row 1 and the filled line moves to row 2, so the next values typed into the top row go into the new line. | N14: /orders/new | O14: Always | P14: BUG-013.jpg, BUG-013-2.jpg, BUG-013-3.jpg, BUG-013-4.jpg, BUG-013-5.png | R14: admin (ADMIN) | T14: 2026-10-11 | U14: R1 | V14: S001 | X14: Closed | Y14: 2026-10-12 R3: fixed - With item line 1 filled (Cotton T-shirt, 61091000, US, 2, 20.00, 0.5), clicking + Add item now appends the blank line as row 2 and leaves the filled line as row 1. 2026-10-13 R4 (build local dev, 2026-10-13): fixed - With item line 1 filled, + Add item appends the blank line below it as row 2; the filled line stays at row 1. 2026-10-13 R5 (build local dev, 2026-10-13 (rebuilt after R4; frontend modules dated 13:12 IST)): fixed - Regression check passed: with item line 1 filled (Cotton T-shirt, 61091000, US, 2, 20.00, 0.5), + Add item appends the blank line as row 2 and the filled line stays in row 1. | Z14: New
A15: BUG-014 | B15: Low | C15: UI | D15: Orders | E15: New order | F15: New order form (international) | G15: Boxes: Spread across 2 boxes | H15: New shipment: the 'Lines spread across 2 boxes' toast covers the Validate shipment and Generate label buttons | I15: 1. Open Orders and click + New shipment (/orders/new) 2. Client: MKL246 (ship from 3PL-EAST, the client default) 3. Carrier: USPS; ship to country Mexico 4. Add another box (2 boxes) 5. Two item lines (Add item) 6. Click Boxes > Spread across 2 boxes | J15: Seen during the run and on retest 2026-10-12 | K15: Confirmation toasts do not sit over the footer's main buttons. | L15: Toast 'Done — Lines spread across 2 boxes in order — adjust any line's Pkg # if needed.' covers Validate shipment and Generate label at the bottom right; during the run the Validate click did not go through until the toast was closed. | N15: /orders/new | O15: Always | P15: BUG-014.jpg, BUG-014-2.jpg, BUG-014-3.jpg | R15: admin (ADMIN) | T15: 2026-10-11 | U15: R1 | V15: S001 | X15: Closed | Y15: 2026-10-12 R3: fixed - With 2 boxes and 2 item lines, Boxes > 'Spread across 2 boxes' shows the toast 'Done - Lines spread across 2 boxes in order - adjust any line's Pkg # if needed.' clear of the footer: Validate shipment and Generate label stay fully visible and clickable while it is on screen. The lines were correctly assigned Pkg # 1 and 2. 2026-10-13 R4 (build local dev, 2026-10-13): fixed - Boxes > 'Spread across 2 boxes' shows 'Done - Lines spread across 2 boxes in order - adjust any line's Pkg # if needed.' clear of the footer, with Validate shipment and Generate label both fully visible and clickable. 2026-10-13 R5 (build local dev, 2026-10-13 (rebuilt after R4; frontend modules dated 13:12 IST)): fixed - Regression check passed: Boxes > 'Spread across 2 boxes' shows the toast 'Done - Lines spread across 2 boxes in order - adjust any line's Pkg # if needed.' at the right, above the footer, with Validate shipment and Generate label clear and clickable; the toast dismisses itself after a few seconds. While it is up it sits over the right end of the minimised Shipment check bar (its 'Check again' and 'Show details' buttons), which is cosmetic because the footer's Validate shipment does the same job. | Z15: New
A16: BUG-015 | B16: Low | C16: Functional | D16: Orders | E16: Label | F16: Label documents | G16: Label preview | H16: Label documents: every page load gets HTTP 503 from HEAD /label/preview.png before falling back to the PDF | I16: 1. Open /label/934119 (or any generated order's label page) 2. Read the network requests | J16: Orders #934118, #934119, #934190 (2026-10-12) | K16: The preview request succeeds, or the page asks for the PDF directly; no 5xx on a normal page load. | L16: HEAD /api/v1/orders/{id}/label/preview.png?pkg=1 -> 503, twice per load, then GET /label/pdf -> 200 and the label shows. Each /label request is also sent twice (possibly React StrictMode in the dev build). | M16: HEAD /api/v1/orders/934119/label/preview.png?pkg=1 -> 503 (x2); GET /api/v1/orders/934119/label -> 200 (x2); GET /api/v1/orders/934119/label/pdf -> 200 | N16: /label/{orderNo} | O16: Always (3 of 3 pages) | P16: Not captured | R16: admin (ADMIN) | T16: 2026-10-12 | U16: R1 | V16: S003 | X16: Closed | Y16: 2026-10-12 R3: still-failing - Unchanged. On /label/934119 and /label/934118 the page still sends HEAD /api/v1/orders/{id}/label/preview.png?pkg=1 -> 503 twice per load before falling back to GET /label/pdf -> 200, and GET /api/v1/orders/{id}/label is still sent twice. 2026-10-13 R4 (build local dev, 2026-10-13): still-failing - Unchanged. /label/934119 still sends HEAD /api/v1/orders/934119/label/preview.png?pkg=1 -> 503 twice per page load before falling back to GET /label/pdf -> 200, and GET /api/v1/orders/934119/label is still sent twice. 2026-10-13 R5 (build local dev, 2026-10-13 (rebuilt after R4; frontend modules dated 13:12 IST)): fixed - No 5xx any more. Opening the label page of the new order #934192 sends HEAD /api/v1/orders/934192/label/preview.png?pkg=1 -> 404 (twice, about 120 ms each) and then GET /label/pdf?pkg=1 -> 200 in 50 ms, and the label renders; no console error. The page still probes for a PNG preview that never exists for this carrier, now answered with a clean 404 instead of 503, and GET /label is still sent twice per load (React StrictMode in dev). | Z16: Fixed | AB16: Fixed on dev (d52bc26f): HEAD short-circuit shipped 2026-10-12; verified via curl: HEAD now returns 404 not 503. QA R4 stale backend. | AC16: 2026-10-13
A17: BUG-016 | B17: Low | C17: Content | D17: Orders | E17: New order | F17: New order form (international) | G17: Validate shipment | H17: Validate shipment: a server failure shows the raw toast 'Something went wrong HTTP error! status: 502' | I17: 1. Open Orders and click + New shipment (/orders/new) 2. Client: MKL246 (ship from 3PL-EAST, the client default) 3. Carrier: FedEx 4. Ship to: Full name QA Test Recipient, Company QA Test Co, Address line 1 Av Paseo de la Reforma 222, Country Mexico (MX), Phone 5552081234, State / region CMX, City Ciudad de Mexico, Postal code 06600 5. Service level: FedEx International Economy; Packaging FedEx Pak; 2 boxes 6. Fill customs, importer and items as for the other Mexico FedEx orders 7. Click Validate shipment | J17: First Validate of MX-FX-IE-PAK (order later created as #934153) | K17: A plain message that the check could not run and to try again; no HTTP wording. | L17: Toast 'Something went wrong HTTP error! status: 502'; no check panel and no order. Clicking Validate again worked. | N17: /orders/new | O17: 1 of about 40 FedEx validations | P17: Not captured | R17: admin (ADMIN) | T17: 2026-10-11 | U17: R1 | V17: S001 | X17: Closed | Y17: 2026-10-12 R3: cannot-retest - The 502 was a one-off server failure and could not be provoked again. Validate shipment was run about a dozen times during this retest across FedEx, UPS and USPS on the Canada, Mexico and UK lanes and returned 200 every time, so the raw 'Something went wrong HTTP error! status: 502' toast never reappeared. The wording of the error path is therefore unverified; note that other raw text is still shown to the user - the USPS no-price message prints the carrier's JSON ('error_reference_id ... error_code 4522242 ...') in full inside the check panel. 2026-10-13 R4 (build local dev, 2026-10-13): cannot-retest - The 502 from /shipments/validate could not be provoked again - about fifteen validations across FedEx, UPS and USPS on the Canada, Mexico and UK lanes all returned 200. A related case did appear and is worth the team's attention: when the FedEx sandbox returned 503, the check panel printed the raw status to the user - 'No price from the carrier: No price: FEDEX rate call failed - HTTP 503 The service is currently unavailable...'. The carrier's own sentence is fine; the 'HTTP 503' prefix is the same raw-status habit the original bug was about. 2026-10-13 R5 (build local dev, 2026-10-13 (rebuilt after R4; frontend modules dated 13:12 IST)): cannot-retest - The one-off 502 from /shipments/validate did not recur: about ten validations across USPS and FedEx in this run returned 200. The raw-status habit behind it is still visible in another place, though: whenever the FedEx sandbox rate call fails, the check panel prints 'No price from the carrier: No price: FEDEX rate call failed - HTTP 503 The service is currently unavailable...' (and once 'HTTP 500 GENERIC.ERROR'), twice in the same panel. That is now logged as its own bug so it can be fixed independently of the toast. 2026-10-14 R6 (build local dev, 2026-10-14 (order-form modules reloaded 13:17 IST)): fixed - R6: the real 502 never recurred, so the failure was simulated in the page: the next POST /api/v1/shipments/validate was answered with an HTML 502 Bad Gateway. The toast now reads 'Something went wrong - Backend is temporarily unavailable - please try again in a moment.' with no HTTP wording, and the form stays as it was. (The previous check panel stays open with its old results while the toast shows.) | Z17: Fixed | AB17: Fixed on dev (cleanServerMessage): cleanServerMessage already strips HTTP prefix. One-off 502 not reproducible. | AC17: 2026-10-13
A18: BUG-017 | C18: Query | D18: API | E18: Orders | F18: Order detail (GET /api/v1/orders/{id}) | G18: shippingDetails.weight | H18: Order API: shippingDetails.weight holds one box's weight on two-box orders, not the shipment total - intended? | I18: 1. GET /api/v1/orders/934190 (2 boxes of 2 lb) 2. Read data.shippingDetails.weight and data.orderDetails.packageCount | J18: All 97 two-box orders of the run, e.g. #934190 (2 x 2 lb), #934172 (THB 2 x 5 lb) | K18: If the field is the order weight, it should be the total (4 lb, 10 lb); if it is per box, the name or docs should say so and per-box weights should be available. | L18: weight 2 for #934190 and 5 for #934172; on all 97 two-box orders it equals one box's weight. | N18: /api/v1/orders/{id} | O18: Always (97 of 97) | P18: Not captured | R18: admin (ADMIN) | T18: 2026-10-11 | U18: R1 | V18: S004 | X18: Reopened | Y18: 2026-10-12 R3: still-failing - Unchanged. GET /api/v1/orders/934190 returns orderDetails.packageCount 2 with shippingDetails.weight 2 (the shipment is 2 boxes of 2 lb, so the total is 4); #934172 returns packageCount 2 with weight 5 against a 10 lb total. shippingDetails still carries only city, state, zipCode, shipVia, weight, shipViaDescription and intlYn - there is no per-box weight array and no renamed field, so the ambiguity the bug asked about is unresolved. 2026-10-13 R4 (build local dev, 2026-10-13): still-failing - Unchanged. shippingDetails.weight still holds one box's weight on multi-box orders: #934190 packageCount 2 / weight 2 (total 4), #934172 packageCount 2 / weight 5 (total 10), and the new #934191 packageCount 2 / weight 3 (total 6). No per-box weight array and no renamed field have been added. 2026-10-13 R5 (build local dev, 2026-10-13 (rebuilt after R4; frontend modules dated 13:12 IST)): still-failing - Fixed for every GENERATED order checked, not for orders that never got a label. New two-box order #934192 (2 x 5 lb) reports shippingDetails.weight 10, and the backfill corrected the old ones: #934190 now 4 (was 2) and #934172 now 10 (was 5). But the two-box ERROR orders still hold one box's weight: #934191 reports 3 for a 6 lb shipment (2 x 3 lb) and #934106 reports 5 for 10 lb (2 x 5 lb), both unchanged since R4. The backfill appears to work from label batches, which ERROR orders do not have, so the field still means 'total' or 'one box' depending on the order's status. The new FedEx two-box order #934193 (2 x 3 lb FedEx Tube) also reports weight 6, so new orders are correct on both carriers tried. 2026-10-14 R6 (build local dev, 2026-10-14 (order-form modules reloaded 13:17 IST)): still-failing - R6: unchanged for orders that never got a label: ERROR orders #934191 (2 boxes, 2 x 3 lb) reports shippingDetails.weight 3 and #934106 (2 x 5 lb) reports 5. GENERATED orders stay correct: #934190 4, #934172 10, #934192 10. 2026-10-16 R7 (build local dev, 2026-10-16): still-failing - unchanged for orders that never got a label: ERROR orders #934191 (packageCount 2, 2 x 3 lb) and #934106 (packageCount 2, 2 x 5 lb) still report shippingDetails.weight 3 and 5. GENERATED orders stay correct: #934190 4, #934172 10, #934192 10. Matches the developers' own note that the ERROR path was missed by the backfill. | Z18: Deferred | AB18: Deferred to next round: Code fix covers new orders; ERROR path missed by V150 — needs broader backfill. | AC18: 2026-10-13
